Workbook

Sheet Master Sheet
A1: Product Name | B1: SKU | C1: UPC/EAN | D1: Brand | E1: ASIN | F1: Model No. | G1: Product Name | H1: Description | I1: Color | J1: Fabric | K1: MRP | L1: HSN | M1: GST | N1: Quantity 1st Lot | O1: Sales | P1: FOB 1st Lot | Q1: DP | R1: Gross Weight (kg) | S1: L | T1: W | U1: H | V1: Volumetric Weight | AB1: =SUM(AB2:AB9)*40 -> 640 | AC1: =SUM(AC2:AC9)*40 -> 720 | AD1: =SUM(AD2:AD9)*40 -> 720 | AE1: =SUM(AE2:AE9)*40 -> 720 | AF1: =SUM(AF2:AF9)*40 -> 640 | AG1: =SUM(AG2:AG9)*40 -> 720
A2: Nexlev Falcon Series Gaming Chair with Fabric and Vegan Leather Upholstery - Black | B2: FBA75664 | C2: 8904422500006 | D2: Nexlev | E2: B0B5HCTGN5 | F2: FD-22-BK | G2: Nexlev Falcon Series Gaming Chair with Fabric and Vegan Leather Upholstery - Black | H2: Falcon Series Gaming Chair FD-22-BK | I2: Black | K2: 24999 | L2: 94013900 | M2: 0.18 | N2: 52 | O2: =VLOOKUP(F2,[3]Sheet3!$B$2:$E$9,4,0) -> #N/A | P2: 60.75 | Q2: 7927.713 | R2: 21 | S2: 67 | T2: 33 | U2: 87 | V2: =S2*T2*U2/5000 -> 38.4714 | AB2: 2 | AC2: 3 | AD2: 3 | AE2: 3 | AF2: 2 | AG2: 3
A3: Nexlev Falcon Series Gaming Chair with Fabric and Vegan Leather Upholstery - Red | B3: FBA75665 | C3: 8904422501713 | D3: Nexlev | E3: B0B5HCG8MM | F3: FD-22-RD | G3: Nexlev Falcon Series Gaming Chair with Fabric and Vegan Leather Upholstery - Red | H3: Falcon Series Gaming Chair FD-22-RD | I3: Red | K3: 24999 | L3: 94013900 | M3: 0.18 | N3: 52 | O3: =VLOOKUP(F3,[3]Sheet3!$B$2:$E$9,4,0) -> #N/A | P3: 60.75 | Q3: 7927.713 | R3: 21 | S3: 67 | T3: 33 | U3: 87 | V3: =S3*T3*U3/5000 -> 38.4714 | AB3: 2 | AC3: 3 | AD3: 3 | AE3: 3 | AF3: 2 | AG3: 3
A4: Nexlev Maverick Series Gaming Chair with Fabric Upholstery - Black | B4: FBA75666 | C4: 8904422501720 | D4: Nexlev | E4: B0B5HB1HJH | F4: MF-22-BK | G4: Nexlev Maverick Series Gaming Chair with Fabric Upholstery - Black | H4: Maverick Series Gaming Chair MF-22-BK | I4: Black | J4: Fabric | K4: 29999 | L4: 94013900 | M4: 0.18 | N4: 60 | O4: =VLOOKUP(F4,[3]Sheet3!$B$2:$E$9,4,0) -> #N/A | P4: 81.35 | Q4: 10094.235 | R4: 24 | S4: 83 | T4: 65 | U4: 37 | V4: =S4*T4*U4/5000 -> 39.923 | AB4: 3 | AC4: 3 | AD4: 3 | AE4: 3 | AF4: 3 | AG4: 3
A5: Nexlev Maverick Series Gaming Chair with Fabric Upholstery - Red | B5: FBA75667 | C5: 8904422501737 | D5: Nexlev | E5: B0B5HFGQGM | F5: MF-22-RD | G5: Nexlev Maverick Series Gaming Chair with Fabric Upholstery - Red | H5: Maverick Series Gaming Chair MF-22-RD | I5: Red | J5: Fabric | K5: 29999 | L5: 94013900 | M5: 0.18 | N5: 41 | O5: =VLOOKUP(F5,[3]Sheet3!$B$2:$E$9,4,0) -> #N/A | P5: 81.35 | Q5: 10094.235 | R5: 24 | S5: 83 | T5: 65 | U5: 37 | V5: =S5*T5*U5/5000 -> 39.923 | AB5: 2 | AC5: 2 | AD5: 2 | AE5: 2 | AF5: 2 | AG5: 2
A6: Nexlev Maverick Series Gaming Chair with Fabric Upholstery - Blue | B6: FBA75668 | C6: 8904422501744 | D6: Nexlev | E6: B0B5F78LMB | F6: MF-22-BL | G6: Nexlev Maverick Series Gaming Chair with Fabric Upholstery - Blue | H6: Maverick Series Gaming Chair MF-22-BL | I6: Blue | J6: Fabric | K6: 29999 | L6: 94013900 | M6: 0.18 | N6: 25 | O6: =VLOOKUP(F6,[3]Sheet3!$B$2:$E$9,4,0) -> #N/A | P6: 81.35 | Q6: 10094.235 | R6: 24 | S6: 83 | T6: 65 | U6: 37 | V6: =S6*T6*U6/5000 -> 39.923 | AB6: 1 | AC6: 1 | AD6: 1 | AE6: 1 | AF6: 1 | AG6: 1
A7: Nexlev Maverick Series Gaming Chair with Vegan Leather Upholstery - Black | B7: FBA75669 | C7: 8904422501751 | D7: Nexlev | E7: B0B5HFG6W7 | F7: ML-22-BK | G7: Nexlev Maverick Series Gaming Chair with Vegan Leather Upholstery - Black | H7: Maverick Series Gaming Chair ML-22-BK | I7: Black | J7: Leather | K7: 29999 | L7: 94013900 | M7: 0.18 | N7: 60 | O7: =VLOOKUP(F7,[3]Sheet3!$B$2:$E$9,4,0) -> #N/A | P7: 81.35 | Q7: 10094.235 | R7: 24 | S7: 83 | T7: 65 | U7: 37 | V7: =S7*T7*U7/5000 -> 39.923 | AB7: 3 | AC7: 3 | AD7: 3 | AE7: 3 | AF7: 3 | AG7: 3
A8: Nexlev Maverick Series Gaming Chair with Vegan Leather Upholstery - Red | B8: FBA75670 | C8: 8904422501768 | D8: Nexlev | E8: B0B5HDPTLC | F8: ML-22-RD | G8: Nexlev Maverick Series Gaming Chair with Vegan Leather Upholstery - Red | H8: Maverick Series Gaming Chair ML-22-RD | I8: Red | J8: Leather | K8: 29999 | L8: 94013900 | M8: 0.18 | N8: 40 | O8: =VLOOKUP(F8,[3]Sheet3!$B$2:$E$9,4,0) -> #N/A | P8: 81.35 | Q8: 10094.235 | R8: 24 | S8: 83 | T8: 65 | U8: 37 | V8: =S8*T8*U8/5000 -> 39.923 | AB8: 2 | AC8: 2 | AD8: 2 | AE8: 2 | AF8: 2 | AG8: 2
A9: Nexlev Maverick Series Gaming Chair with Vegan Leather Upholstery - Blue | B9: FBA75671 | C9: 8904422501775 | D9: Nexlev | E9: B0B5HCN3TJ | F9: ML-22-BL | G9: Nexlev Maverick Series Gaming Chair with Vegan Leather Upholstery - Blue | H9: Maverick Series Gaming Chair ML-22-BL | I9: Blue | J9: Leather | K9: 29999 | L9: 94013900 | M9: 0.18 | N9: 25 | O9: =VLOOKUP(F9,[3]Sheet3!$B$2:$E$9,4,0) -> #N/A | P9: 81.35 | Q9: 10094.235 | R9: 24 | S9: 83 | T9: 65 | U9: 37 | V9: =S9*T9*U9/5000 -> 39.923 | AB9: 1 | AC9: 1 | AD9: 1 | AE9: 1 | AF9: 1 | AG9: 1
A10: Nexlev Chronicle Series Gaming RGB Microphone with Tripod | B10: FBA75955 | C10: 8904422501782 | D10: Nexlev | E10: B0B5LM1FWP | F10: CM-22 | G10: Nexlev Chronicle Series Gaming RGB Microphone with Tripod | H10: Chronicle Series Gaming RGB Microphone CM-22 | I10: Black | K10: 9999 | L10: 85181000 | M10: 0.18 | N10: 29 | Q10: 2386.392 | R10: 0.77 | S10: 24 | T10: 17 | U10: 11 | V10: =S10*T10*U10/5000 -> 0.8976
A11: Nexlev Chronicle Series Gaming RGB Microphone with Shock Mount, Pop Filter, and Metal Stand | B11: FBA75956 | C11: 8904422501799 | D11: Nexlev | E11: B0B5LL2ZQR | F11: CM-22 Pro | G11: Nexlev Chronicle Series Gaming RGB Microphone with Shock Mount, Pop Filter, and Metal Stand | H11: Chronicle Series Gaming RGB Microphone CM-22 Pro | I11: Black | K11: 9999 | L11: 85181000 | M11: 0.18 | N11: 35 | Q11: 2892.036 | R11: 0.91 | S11: 26 | T11: 14 | U11: 11 | V11: =S11*T11*U11/5000 -> 0.8008
A12: Nexlev Falcon Series Footrest (Black) | B12: FBA75963 | C12: 8904422501928 | D12: Nexlev | E12: B0B71QN43M | F12: FD-22-FR | G12: Nexlev Falcon Series Footrest (Black) | H12: Falcon Series Footrest | I12: Black | K12: 6999 | L12: 94013900 | M12: 0.18 | N12: 10 | P12: 12.5 | Q12: 1721.148 | R12: 5.7 | S12: 54 | T12: 18 | U12: 51 | V12: =S12*T12*U12/5000 -> 9.9144 | AB12: 1 | AC12: 1 | AD12: 1 | AE12: 1 | AF12: 1 | AG12: 1
A13: Nexlev Maverick Series Footrest (Black) | B13: FBA75964 | C13: 8904422501935 | D13: Nexlev | E13: B0B71QY1TH | F13: ML-22-FR | G13: Nexlev Maverick Series Footrest (Black) | H13: Maverick Series Footrest | I13: Black | K13: 6999 | L13: 94013900 | M13: 0.18 | N13: 10 | P13: 12.5 | Q13: 1721.148 | R13: 5.7 | S13: 54 | T13: 18 | U13: 51 | V13: =S13*T13*U13/5000 -> 9.9144 | AB13: 1 | AC13: 1 | AD13: 1 | AE13: 1 | AF13: 1 | AG13: 1
A14: Nexlev 350mm Heavy Duty Aluminium Base (350mm aluminium base) | B14: FBA75967 | C14: 8904422501966 | D14: Nexlev | E14: B0BC93W1V1 | F14: AB-350 | G14: Nexlev 350mm Heavy Duty Aluminium Base (350mm aluminium base) | H14: 350mm aluminium base | K14: 6399 | L14: 94019900 | M14: 0.18 | N14: 50 | P14: 11.8 | Q14: 1595.55 | R14: 2.5 | S14: 67 | T14: 10 | U14: 65 | V14: =S14*T14*U14/5000 -> 8.71 | Y14: 278 | AA14: SBOB | AB14: SCCE | AC14: SHYG | AD14: SDEB | AE14: SBLB | AF14: SCJF | AG14: SMAC
A15: Nexlev 350mm Heavy Duty Metal Base (350mm metal base) | B15: FBA75968 | C15: 8904422501973 | D15: Nexlev | E15: B0BC99CYXD | F15: MB-350 | G15: Nexlev 350mm Heavy Duty Metal Base (350mm metal base) | H15: 350mm metal base | K15: 3999 | L15: 94019900 | M15: 0.18 | N15: 25 | P15: 5.9 | Q15: 993.75 | R15: 3.1 | S15: 67 | T15: 10 | U15: 65 | V15: =S15*T15*U15/5000 -> 8.71 | Y15: 278 | AB15: Majukhetra (West Bengal) | AC15: Hyderabad (Telangana) | AD15: Luhari Village (Haryana) | AE15: Kolar (Karnataka) | AF15: Coimbatore (Chennai) | AG15: Kanchipuram (Tamil Nadu)
A16: Nexlev 350mm Heavy Duty Nylon Base (350mm nylon base 2) | B16: FBA75969 | C16: 8904422501980 | D16: Nexlev | E16: B0BC93RS1L | F16: NB-350 | G16: Nexlev 350mm Heavy Duty Nylon Base (350mm nylon base 2) | H16: 350mm nylon base | K16: 2499 | L16: 94019900 | M16: 0.18 | N16: 10 | P16: 3.7 | Q16: 769.35 | R16: 2.65 | S16: 67 | T16: 10 | U16: 65 | V16: =S16*T16*U16/5000 -> 8.71 | Y16: 294 | AB16: Kolkata | AC16: Hyderabad | AD16: Delhi | AE16: Bangalore | AF16: Kerala | AG16: Chennai
A17: Nexlev 4D Armrest for Chairs (4D Armrest) | B17: FBA75965 | C17: 8904422501942 | D17: Nexlev | E17: B0BGXYD1ZP | F17: AR-4D | G17: Nexlev 4D Armrest for Chairs (4D Armrest) | H17: 4D Armrest | K17: 5499 | L17: 94019900 | M17: 0.18 | N17: 25 | P17: 10 | Q17: 1235.325 | R17: 3.5 | S17: 25 | T17: 29 | U17: 33 | V17: =S17*T17*U17/5000 -> 4.785 | Y17: 262
A18: Nexlev 3D Armrest for Chairs (3D Armrest) | B18: FBA75966 | C18: 8904422501959 | D18: Nexlev | E18: B0BGXZB3CM | F18: AR-3D | G18: Nexlev 3D Armrest for Chairs (3D Armrest) | H18: 3D Armrest | K18: 4599 | L18: 94019900 | M18: 0.18 | N18: 10 | P18: 7.9 | Q18: 1021.125 | R18: 2.9 | S18: 25 | T18: 29 | U18: 33 | V18: =S18*T18*U18/5000 -> 4.785 | Y18: 181.05
A19: Nexlev Butterfly Tilt Mechanism (Butterfly Mechanism) | B19: FBA75973 | C19: 8904422502024 | D19: Nexlev | E19: B0BGY2XKZ1 | F19: BM-01 | G19: Nexlev Butterfly Tilt Mechanism (Butterfly Mechanism) | H19: Butterfly Mechanism | K19: 2199 | L19: 94019900 | M19: 0.18 | N19: 10 | P19: 2.7 | Q19: 353.439 | R19: 1.75 | S19: 29 | T19: 23 | U19: 13 | V19: =S19*T19*U19/5000 -> 1.7342 | Y19: 197
A20: Nexlev Frog Tilt Mechanism (Frog Mechanism) | B20: FBA75974 | C20: 8904422502031 | D20: Nexlev | E20: B0BGY4MLKX | F20: FM-01 | G20: Nexlev Frog Tilt Mechanism (Frog Mechanism) | H20: Frog Mechanism | K20: 5699 | L20: 94019900 | M20: 0.18 | N20: 25 | P20: 10.4 | Q20: 1226.04 | R20: 3.9 | S20: 34 | T20: 27 | U20: 20 | V20: =S20*T20*U20/5000 -> 3.672 | Y20: 230
A21: Nexlev 75mm Racing Caster Wheels (75mm racing castor with lock) | B21: FBA75971 | C21: 8904422502000 | D21: Nexlev | E21: B0BGY3223L | F21: RC-75 | G21: Nexlev 75mm Racing Caster Wheels (75mm racing castor with lock) | H21: 75mm racing castor with lock | K21: 2499 | L21: 94019900 | M21: 0.18 | N21: 20 | P21: 3.6 | Q21: 382.752 | R21: 1.15 | S21: 8 | T21: 8 | U21: 27 | V21: =S21*T21*U21/5000 -> 0.3456 | Y21: 131
A22: Nexlev In-Line Rollerblade Casters for Chair (75mm Silicon wheel) | B22: FBA75972 | C22: 8904422502017 | D22: Nexlev | E22: B0BGY61JMN | F22: RB-75 | G22: Nexlev In-Line Rollerblade Casters for Chair (75mm Silicon wheel) | H22: 75mm Silicon wheel | K22: 3999 | L22: 94019900 | M22: 0.18 | N22: 20 | P22: 6.5 | Q22: 678.552 | R22: 1.25 | S22: 8 | T22: 8 | U22: 27 | V22: =S22*T22*U22/5000 -> 0.3456 | Y22: 131
A23: Nexlev 60mm Nylon Caster Wheels (60mm PU castor) | B23: FBA75970 | C23: 8904422501997 | D23: Nexlev | E23: B0BGY6R2YQ | F23: NC-60 | G23: Nexlev 60mm Nylon Caster Wheels (60mm PU castor) | H23: 60mm PU castor | K23: 1499 | L23: 94019900 | M23: 0.18 | N23: 35 | P23: 1.3 | Q23: 148.152 | R23: 0.65 | S23: 8 | T23: 8 | U23: 27 | V23: =S23*T23*U23/5000 -> 0.3456 | Y23: 98
A24: Nexlev Gaming Chair Gaslift 80mm | B24: FBA76595 | D24: Nexlev | F24: GL-80 | G24: Nexlev Gaming Chair Gaslift 80mm | H24: 80mm Gaslift | L24: 94019900 | M24: 0.18 | P24: 2.4 | Q24: 260 | R24: 0.8 | S24: 6 | T24: 6 | U24: 30 | V24: =S24*T24*U24/5000 -> 0.216

Sheet Margin Calculation
D1: Primary Channel | E1: Status | F1: SKU | G1: ASIN | H1: Model | I1: Category L1 | J1: Category L2 | K1: Supplier Model | L1: OEM Name | M1: Description | N1: HSN Code | O1: Gross Weight | P1: L | Q1: W | R1: H | S1: CBM/Unit | T1: Vol. Weight | U1: FOB (USD) | V1: Latest FOB | W1: Freight+Clearance | X1: Duty and Surcharge | Y1: DP | Z1: NLC | AA1: Referral Fee | AB1: Fixed Closing Fee | AC1: Fulfillment Fees | AD1: Total FBA Fee | AE1: AMS | AF1: Coupon | AG1: Returns Loss | AH1: SMM | AI1: 18% GST in SP | AJ1: Business overhead expenses | AK1: Cost of finance | AL1: Margin | AM1: Margin% | AN1: BAU Deal SP | AO1: Other Charges | AP1: Juiter SP | AQ1: inventory | AR1: MRP (4X of nlc) | AS1: Min Price | AT1: Max Price | AU1: Updated MRP | AV1: Gross Margin | AW1: Gross Margin % | AX1: EAN | AY1: Landed $ Rate | AZ1: Factor on landing | BA1: Factor on FOB | BB1: Rating | BC1: No of Reviews
F2: FBA75664 | G2: B0B5HCTGN5 | H2: FD-22-BK | I2: Gaming | L2: Anji Bitai | M2: Nexlev Falcon Series Gaming Chair with Premium Fabric & Vegan Leather, Memory Foam Neckrest & Lumbar Cushion, 3D Armrests, Sturdy Nylon Base, Butterfly Mechanism, & Class 4 Gaslift (Black, FD-22-BK) | O2: 21 | P2: 67 | Q2: 33 | R2: 87 | S2: =(P2*Q2*R2)/1000000 -> 0.192357 | T2: =(P2*Q2*R2)/5000 -> 38.4714 | U2: 36 | W2: =B$27/(B$28/S2) -> 5.6575588 | X2: =(U2+W2)*(B$30+(B$30*B$45)) -> 11.455829 | Y2: =(U2+W2+X2)*B$26 -> 4780.2049 | Z2: =Y2*1.18 -> 5640.6418 | AA2: =AN2*IF(AN2<15001,B$64,B$65) -> 1499.85 | AB2: 47 | AC2: 750 | AD2: =AA2+AB2+AC2 -> 2296.85 | AE2: =AN2*B$66 -> 1499.85 | AF2: =AN2*$B$70 -> 199.98 | AG2: =AN2*B$67 -> 499.95 | AH2: =AN2*$B$74 -> 199.98 | AI2: =AN2-(AN2/1.18) -> 1525.2712 | AJ2: =Z2*5% -> 282.03209 | AK2: =Z2*3% -> 169.21925 | AL2: =AN2-Y2-AD2-AE2-AG2-AI2-AJ2-AK2-AF2-AH2 -> -1454.3374 | AM2: =AL2/AN2 -> -0.14544828 | AN2: 9999 | AR2: 24999 | AV2: =SUM(AN2-AI2)-Y2 -> 3693.5239 | AW2: =AV2/AN2 -> 0.36938933 | AY2: =Y2/U2 -> 132.78347 | AZ2: =AN2/+SUM(Y2/84) -> 175.70711 | BA2: =AN2/U2 -> 277.75
F3: FBA75665 | G3: B0B5HCG8MM | H3: FD-22-RD | I3: Gaming | L3: Anji Bitai | M3: Nexlev Falcon Series Gaming Chair with Premium Fabric & Vegan Leather, Memory Foam Neckrest & Lumbar Cushion, 3D Armrests, Sturdy Nylon Base, Butterfly Mechanism, & Class 4 Gaslift (Red, FD-22-RD) | O3: 21 | P3: 67 | Q3: 33 | R3: 87 | S3: =(P3*Q3*R3)/1000000 -> 0.192357 | T3: =(P3*Q3*R3)/5000 -> 38.4714 | U3: 60.75 | W3: =B$27/(B$28/S3) -> 5.6575588 | X3: =(U3+W3)*(B$30+(B$30*B$45)) -> 18.262079 | Y3: =(U3+W3+X3)*B$26 -> 7620.2674 | Z3: =Y3*1.18 -> 8991.9155 | AA3: =AN3*IF(AN3<15001,B$64,B$65) -> 1509.9 | AB3: 47 | AC3: 750 | AD3: =AA3+AB3+AC3 -> 2306.9 | AE3: =AN3*B$66 -> 2264.85 | AF3: =AN3*$B$70 -> 301.98 | AG3: =AN3*B$67 -> 754.95 | AH3: =AN3*$B$74 -> 301.98 | AI3: =AN3-(AN3/1.18) -> 2303.2373 | AJ3: =Z3*5% -> 449.59578 | AK3: =Z3*3% -> 269.75747 | AL3: =AN3-Y3-AD3-AE3-AG3-AI3-AJ3-AK3-AF3-AH3 -> -1474.5179 | AM3: =AL3/AN3 -> -0.09765666 | AN3: 15099 | AR3: 24999 | AV3: =SUM(AN3-AI3)-Y3 -> 5175.4953 | AW3: =AV3/AN3 -> 0.34277074 | AY3: =Y3/U3 -> 125.4365 | AZ3: =AN3/+SUM(Y3/84) -> 166.43983 | BA3: =AN3/U3 -> 248.54321
F4: FBA75666 | G4: B0B5HB1HJH | H4: MF-22-BK | I4: Gaming | L4: Anji Bitai | M4: Nexlev Maverick Series Gaming Chair with Premium Fabric Upholstery, Memory Foam Lumbar Cushion, 4D Armrests, Heavy Duty Metal Base, Frog Mechanism, & Class 4 Gaslift (Black, MF-22-BK) | O4: 24 | P4: 83 | Q4: 65 | R4: 37 | S4: =(P4*Q4*R4)/1000000 -> 0.199615 | T4: =(P4*Q4*R4)/5000 -> 39.923 | U4: 76.5 | W4: =B$27/(B$28/S4) -> 5.8710294 | X4: =(U4+W4)*(B$30+(B$30*B$45)) -> 22.652033 | Y4: =(U4+W4+X4)*B$26 -> 9452.0756 | Z4: =Y4*1.18 -> 11153.449 | AA4: =AN4*IF(AN4<15001,B$64,B$65) -> 1699.9 | AB4: 47 | AC4: 750 | AD4: =AA4+AB4+AC4 -> 2496.9 | AE4: =AN4*B$66 -> 2549.85 | AF4: =AN4*$B$70 -> 339.98 | AG4: =AN4*B$67 -> 849.95 | AH4: =AN4*$B$74 -> 339.98 | AI4: =AN4-(AN4/1.18) -> 2593.0678 | AJ4: =Z4*5% -> 557.67246 | AK4: =Z4*3% -> 334.60348 | AL4: =AN4-Y4-AD4-AE4-AG4-AI4-AJ4-AK4-AF4-AH4 -> -2515.0794 | AM4: =AL4/AN4 -> -0.14795455 | AN4: 16999 | AR4: 29999 | AV4: =SUM(AN4-AI4)-Y4 -> 4953.8566 | AW4: =AV4/AN4 -> 0.29142047 | AY4: =Y4/U4 -> 123.55654 | AZ4: =AN4/+SUM(Y4/84) -> 151.06904 | BA4: =AN4/U4 -> 222.20915
F5: FBA75667 | G5: B0B5HFGQGM | H5: MF-22-RD | I5: Gaming | L5: Anji Bitai | M5: Nexlev Maverick Series Gaming Chair with Premium Fabric Upholstery, Memory Foam Lumbar Cushion, 4D Armrests, Heavy Duty Metal Base, Frog Mechanism, & Class 4 Gaslift (Red & Black, MF-22-RD) | O5: 24 | P5: 83 | Q5: 65 | R5: 37 | S5: =(P5*Q5*R5)/1000000 -> 0.199615 | T5: =(P5*Q5*R5)/5000 -> 39.923 | U5: 81.35 | W5: =B$27/(B$28/S5) -> 5.8710294 | X5: =(U5+W5)*(B$30+(B$30*B$45)) -> 23.985783 | Y5: =(U5+W5+X5)*B$26 -> 10008.613 | Z5: =Y5*1.18 -> 11810.163 | AA5: =AN5*IF(AN5<15001,B$64,B$65) -> 1699.9 | AB5: 47 | AC5: 750 | AD5: =AA5+AB5+AC5 -> 2496.9 | AE5: =AN5*B$66 -> 2549.85 | AF5: =AN5*$B$70 -> 339.98 | AG5: =AN5*B$67 -> 849.95 | AH5: =AN5*$B$74 -> 339.98 | AI5: =AN5-(AN5/1.18) -> 2593.0678 | AJ5: =Z5*5% -> 590.50817 | AK5: =Z5*3% -> 354.3049 | AL5: =AN5-Y5-AD5-AE5-AG5-AI5-AJ5-AK5-AF5-AH5 -> -3124.154 | AM5: =AL5/AN5 -> -0.18378458 | AN5: 16999 | AR5: 29999 | AV5: =SUM(AN5-AI5)-Y5 -> 4397.3191 | AW5: =AV5/AN5 -> 0.25868104 | AY5: =Y5/U5 -> 123.03151 | AZ5: =AN5/+SUM(Y5/84) -> 142.66872 | BA5: =AN5/U5 -> 208.96128
F6: FBA75668 | G6: B0B5F78LMB | H6: MF-22-BL | I6: Gaming | L6: Anji Bitai | M6: Nexlev Maverick Series Gaming Chair with Premium Fabric, Molded Foam Seat & Back, Memory Foam Lumbar Cushion, 4D Armrests, Sturdy Metal Base, Frog Mechanism, & Class 4 Gaslift (Blue, MF-22-BL) | O6: 24 | P6: 83 | Q6: 65 | R6: 37 | S6: =(P6*Q6*R6)/1000000 -> 0.199615 | T6: =(P6*Q6*R6)/5000 -> 39.923 | U6: 81.35 | W6: =B$27/(B$28/S6) -> 5.8710294 | X6: =(U6+W6)*(B$30+(B$30*B$45)) -> 23.985783 | Y6: =(U6+W6+X6)*B$26 -> 10008.613 | Z6: =Y6*1.18 -> 11810.163 | AA6: =AN6*IF(AN6<15001,B$64,B$65) -> 1699.9 | AB6: 47 | AC6: 750 | AD6: =AA6+AB6+AC6 -> 2496.9 | AE6: =AN6*B$66 -> 2549.85 | AF6: =AN6*$B$70 -> 339.98 | AG6: =AN6*B$67 -> 849.95 | AH6: =AN6*$B$74 -> 339.98 | AI6: =AN6-(AN6/1.18) -> 2593.0678 | AJ6: =Z6*5% -> 590.50817 | AK6: =Z6*3% -> 354.3049 | AL6: =AN6-Y6-AD6-AE6-AG6-AI6-AJ6-AK6-AF6-AH6 -> -3124.154 | AM6: =AL6/AN6 -> -0.18378458 | AN6: 16999 | AR6: 29999 | AV6: =SUM(AN6-AI6)-Y6 -> 4397.3191 | AW6: =AV6/AN6 -> 0.25868104 | AY6: =Y6/U6 -> 123.03151 | AZ6: =AN6/+SUM(Y6/84) -> 142.66872 | BA6: =AN6/U6 -> 208.96128
F7: FBA75669 | G7: B0B5HFG6W7 | H7: ML-22-BK | I7: Gaming | L7: Anji Bitai | M7: Nexlev Maverick Series Gaming Chair with Premium Vegan Leather Upholstery, Memory Foam Lumbar Cushion, 4D Armrests, Sturdy Metal Base, Frog Mechanism, and Class 4 Gaslift (Black, ML-22-BK) | O7: 24 | P7: 83 | Q7: 65 | R7: 37 | S7: =(P7*Q7*R7)/1000000 -> 0.199615 | T7: =(P7*Q7*R7)/5000 -> 39.923 | U7: 81.35 | W7: =B$27/(B$28/S7) -> 5.8710294 | X7: =(U7+W7)*(B$30+(B$30*B$45)) -> 23.985783 | Y7: =(U7+W7+X7)*B$26 -> 10008.613 | Z7: =Y7*1.18 -> 11810.163 | AA7: =AN7*IF(AN7<15001,B$64,B$65) -> 1699.9 | AB7: 47 | AC7: 750 | AD7: =AA7+AB7+AC7 -> 2496.9 | AE7: =AN7*B$66 -> 2549.85 | AF7: =AN7*$B$70 -> 339.98 | AG7: =AN7*B$67 -> 849.95 | AH7: =AN7*$B$74 -> 339.98 | AI7: =AN7-(AN7/1.18) -> 2593.0678 | AJ7: =Z7*5% -> 590.50817 | AK7: =Z7*3% -> 354.3049 | AL7: =AN7-Y7-AD7-AE7-AG7-AI7-AJ7-AK7-AF7-AH7 -> -3124.154 | AM7: =AL7/AN7 -> -0.18378458 | AN7: 16999 | AR7: 29999 | AV7: =SUM(AN7-AI7)-Y7 -> 4397.3191 | AW7: =AV7/AN7 -> 0.25868104 | AY7: =Y7/U7 -> 123.03151 | AZ7: =AN7/+SUM(Y7/84) -> 142.66872 | BA7: =AN7/U7 -> 208.96128
F8: FBA75670 | G8: B0B5HDPTLC | H8: ML-22-RD | I8: Gaming | L8: Anji Bitai | M8: Nexlev Maverick Series Gaming Chair with Premium Vegan Leather Upholstery, Memory Foam Lumbar Cushion, 4D Armrests, Sturdy Metal Base, Frog Mechanism, and Class 4 Gaslift (Red & Black, ML-22-RD) | O8: 24 | P8: 83 | Q8: 65 | R8: 37 | S8: =(P8*Q8*R8)/1000000 -> 0.199615 | T8: =(P8*Q8*R8)/5000 -> 39.923 | U8: 81.35 | W8: =B$27/(B$28/S8) -> 5.8710294 | X8: =(U8+W8)*(B$30+(B$30*B$45)) -> 23.985783 | Y8: =(U8+W8+X8)*B$26 -> 10008.613 | Z8: =Y8*1.18 -> 11810.163 | AA8: =AN8*IF(AN8<15001,B$64,B$65) -> 1699.9 | AB8: 47 | AC8: 750 | AD8: =AA8+AB8+AC8 -> 2496.9 | AE8: =AN8*B$66 -> 2549.85 | AF8: =AN8*$B$70 -> 339.98 | AG8: =AN8*B$67 -> 849.95 | AH8: =AN8*$B$74 -> 339.98 | AI8: =AN8-(AN8/1.18) -> 2593.0678 | AJ8: =Z8*5% -> 590.50817 | AK8: =Z8*3% -> 354.3049 | AL8: =AN8-Y8-AD8-AE8-AG8-AI8-AJ8-AK8-AF8-AH8 -> -3124.154 | AM8: =AL8/AN8 -> -0.18378458 | AN8: 16999 | AR8: 29999 | AV8: =SUM(AN8-AI8)-Y8 -> 4397.3191 | AW8: =AV8/AN8 -> 0.25868104 | AY8: =Y8/U8 -> 123.03151 | AZ8: =AN8/+SUM(Y8/84) -> 142.66872 | BA8: =AN8/U8 -> 208.96128
F9: FBA75671 | G9: B0B5HCN3TJ | H9: C-04 | I9: Gaming | L9: Anji Bitai | M9: Nexlev Maverick Series Gaming Chair with Premium Vegan Leather Upholstery, Memory Foam Lumbar Cushion, 4D Armrests, Sturdy Metal Base, Frog Mechanism, and Class 4 Gaslift (Blue and Black, ML-22-BL) | O9: 24 | P9: 83 | Q9: 65 | R9: 37 | S9: =(P9*Q9*R9)/1000000 -> 0.199615 | T9: =(P9*Q9*R9)/5000 -> 39.923 | U9: 81.35 | W9: =B$27/(B$28/S9) -> 5.8710294 | X9: =(U9+W9)*(B$30+(B$30*B$45)) -> 23.985783 | Y9: =(U9+W9+X9)*B$26 -> 10008.613 | Z9: =Y9*1.18 -> 11810.163 | AA9: =AN9*IF(AN9<15001,B$64,B$65) -> 1699.9 | AB9: 47 | AC9: 750 | AD9: =AA9+AB9+AC9 -> 2496.9 | AE9: =AN9*B$66 -> 2549.85 | AF9: =AN9*$B$70 -> 339.98 | AG9: =AN9*B$67 -> 849.95 | AH9: =AN9*$B$74 -> 339.98 | AI9: =AN9-(AN9/1.18) -> 2593.0678 | AJ9: =Z9*5% -> 590.50817 | AK9: =Z9*3% -> 354.3049 | AL9: =AN9-Y9-AD9-AE9-AG9-AI9-AJ9-AK9-AF9-AH9 -> -3124.154 | AM9: =AL9/AN9 -> -0.18378458 | AN9: 16999 | AR9: 29999 | AV9: =SUM(AN9-AI9)-Y9 -> 4397.3191 | AW9: =AV9/AN9 -> 0.25868104 | AY9: =Y9/U9 -> 123.03151 | AZ9: =AN9/+SUM(Y9/84) -> 142.66872 | BA9: =AN9/U9 -> 208.96128
F10: FBA75955 | G10: B0B5LM1FWP | H10: CM-22 | I10: Gaming | L10: Anji Bitai | M10: Nexlev USB Condenser Microphone Kit With Tripod For Gaming, Streaming & Meeting, Plug & Play, 2-In-1 Cable For Windows, MAC & PS4/5, No-Latency Monitoring, One Button Mute & Volume Control (CM-22) | O10: 0.77 | P10: 24 | Q10: 17 | R10: 11 | S10: =(P10*Q10*R10)/1000000 -> 0.004488 | T10: =(P10*Q10*R10)/5000 -> 0.8976 | U10: 20 | W10: =B$27/(B$28/S10) -> 0.132 | X10: =(U10+W10)*(0.15+(0.15*B$45)) -> 3.32178 | Y10: =(U10+W10+X10)*B$26 -> 2110.8402 | Z10: =Y10*1.18 -> 2490.7914 | AA10: =AN10*IF(AN10<15001,B$64,B$65) -> 524.85 | AB10: 47 | AC10: 131 | AD10: =AA10+AB10+AC10 -> 702.85 | AE10: =AN10*B$66 -> 524.85 | AF10: =AN10*$B$70 -> 69.98 | AG10: =AN10*B$67 -> 174.95 | AH10: =AN10*$B$74 -> 69.98 | AI10: =AN10-(AN10/1.18) -> 533.74576 | AJ10: =Z10*5% -> 124.53957 | AK10: =Z10*3% -> 74.723743 | AL10: =AN10-Y10-AD10-AE10-AG10-AI10-AJ10-AK10-AF10-AH10 -> -887.45928 | AM10: =AL10/AN10 -> -0.25363226 | AN10: 3499 | AR10: 9999 | AV10: =SUM(AN10-AI10)-Y10 -> 854.41404 | AW10: =AV10/AN10 -> 0.24418806 | AY10: =Y10/U10 -> 105.54201 | AZ10: =AN10/+SUM(Y10/84) -> 139.24124 | BA10: =AN10/U10 -> 174.95
F11: FBA75956 | G11: B0B5LL2ZQR | H11: CM-22 Pro | I11: Gaming | L11: Anji Bitai | M11: Nexlev USB Condenser Microphone for YouTube,Gaming, Meeting & Recording on Mac OS,Windows & PS 4/5 with Pop Filter, Shock Mount & Tripod, No Latency Monitoring,Volume Control & Mute Button(CM-22 PRO) | O11: 0.91 | P11: 26 | Q11: 14 | R11: 11 | S11: =(P11*Q11*R11)/1000000 -> 0.004004 | T11: =(P11*Q11*R11)/5000 -> 0.8008 | U11: 25 | W11: =B$27/(B$28/S11) -> 0.11776471 | X11: =(U11+W11)*(0.15+(0.15*B$45)) -> 4.1444312 | Y11: =(U11+W11+X11)*B$26 -> 2633.5976 | Z11: =Y11*1.18 -> 3107.6452 | AA11: =AN11*IF(AN11<15001,B$64,B$65) -> 644.85 | AB11: 47 | AC11: 98 | AD11: =AA11+AB11+AC11 -> 789.85 | AE11: =AN11*B$66 -> 644.85 | AF11: =AN11*$B$70 -> 85.98 | AG11: =AN11*B$67 -> 214.95 | AH11: =AN11*$B$74 -> 85.98 | AI11: =AN11-(AN11/1.18) -> 655.77966 | AJ11: =Z11*5% -> 155.38226 | AK11: =Z11*3% -> 93.229356 | AL11: =AN11-Y11-AD11-AE11-AG11-AI11-AJ11-AK11-AF11-AH11 -> -1060.5989 | AM11: =AL11/AN11 -> -0.24670828 | AN11: 4299 | AR11: 11999 | AV11: =SUM(AN11-AI11)-Y11 -> 1009.6227 | AW11: =AV11/AN11 -> 0.2348506 | AY11: =Y11/U11 -> 105.34391 | AZ11: =AN11/+SUM(Y11/84) -> 137.1189 | BA11: =AN11/U11 -> 171.96
F12: FBA75963 | G12: B0B71QN43M | H12: FD-22-FR | I12: Gaming | L12: Anji Bitai | M12: Nexlev Falcon Series Footrest with Premium Fabric and Vegan Leather Upholstery (Black) | O12: 5.7 | P12: 54 | Q12: 18 | R12: 51 | S12: =(P12*Q12*R12)/1000000 -> 0.049572 | T12: =(P12*Q12*R12)/5000 -> 9.9144 | U12: 12.5 | W12: =B$27/(B$28/S12) -> 1.458 | X12: =(U12+W12)*(B$30+(B$30*B$45)) -> 3.83845 | Y12: =(U12+W12+X12)*B$26 -> 1601.6805 | Z12: =Y12*1.18 -> 1889.983 | AA12: =AN12*IF(AN12<15001,B$64,B$65) -> 449.85 | AB12: 47 | AC12: 156 | AD12: =AA12+AB12+AC12 -> 652.85 | AE12: =AN12*B$66 -> 449.85 | AF12: =AN12*$B$70 -> 59.98 | AG12: =AN12*B$67 -> 149.95 | AH12: =AN12*$B$74 -> 59.98 | AI12: =AN12-(AN12/1.18) -> 457.47458 | AJ12: =Z12*5% -> 94.499149 | AK12: =Z12*3% -> 56.69949 | AL12: =AN12-Y12-AD12-AE12-AG12-AI12-AJ12-AK12-AF12-AH12 -> -583.96372 | AM12: =AL12/AN12 -> -0.19471948 | AN12: 2999 | AR12: 6999 | AV12: =SUM(AN12-AI12)-Y12 -> 939.84492 | AW12: =AV12/AN12 -> 0.3133861 | AY12: =Y12/U12 -> 128.13444 | AZ12: =AN12/+SUM(Y12/84) -> 157.2823 | BA12: =AN12/U12 -> 239.92
F13: FBA75964 | G13: B0B71QY1TH | H13: ML-22-FR | I13: Gaming | L13: Anji Bitai | M13: Nexlev Maverick Series Footrest with Vegan Leather Upholstery (Black) | O13: 5.7 | P13: 54 | Q13: 18 | R13: 51 | S13: =(P13*Q13*R13)/1000000 -> 0.049572 | T13: =(P13*Q13*R13)/5000 -> 9.9144 | U13: 12.5 | W13: =B$27/(B$28/S13) -> 1.458 | X13: =(U13+W13)*(B$30+(B$30*B$45)) -> 3.83845 | Y13: =(U13+W13+X13)*B$26 -> 1601.6805 | Z13: =Y13*1.18 -> 1889.983 | AA13: =AN13*IF(AN13<15001,B$64,B$65) -> 449.85 | AB13: 47 | AC13: 202 | AD13: =AA13+AB13+AC13 -> 698.85 | AE13: =AN13*B$66 -> 449.85 | AF13: =AN13*$B$70 -> 59.98 | AG13: =AN13*B$67 -> 149.95 | AH13: =AN13*$B$74 -> 59.98 | AI13: =AN13-(AN13/1.18) -> 457.47458 | AJ13: =Z13*5% -> 94.499149 | AK13: =Z13*3% -> 56.69949 | AL13: =AN13-Y13-AD13-AE13-AG13-AI13-AJ13-AK13-AF13-AH13 -> -629.96372 | AM13: =AL13/AN13 -> -0.21005792 | AN13: 2999 | AR13: 6999 | AV13: =SUM(AN13-AI13)-Y13 -> 939.84492 | AW13: =AV13/AN13 -> 0.3133861 | AY13: =Y13/U13 -> 128.13444 | AZ13: =AN13/+SUM(Y13/84) -> 157.2823 | BA13: =AN13/U13 -> 239.92
F14: FBA75967 | G14: B0BC93W1V1 | H14: AB-350 | I14: Gaming | L14: Anji Bitai | M14: Nexlev 350mm Heavy Duty Aluminium Base | O14: 2.5 | P14: 67 | Q14: 10 | R14: 65 | S14: =(P14*Q14*R14)/1000000 -> 0.04355 | T14: =(P14*Q14*R14)/5000 -> 8.71 | U14: 11.8 | W14: =B$27/(B$28/S14) -> 1.2808824 | X14: =(U14+W14)*(B$30+(B$30*B$45)) -> 3.5972426 | Y14: =(U14+W14+X14)*B$26 -> 1501.0313 | Z14: =Y14*1.18 -> 1771.2169 | AA14: =AN14*IF(AN14<15001,B$64,B$65) -> 524.85 | AB14: 47 | AC14: 278 | AD14: =AA14+AB14+AC14 -> 849.85 | AE14: =AN14*B$66 -> 524.85 | AF14: =AN14*$B$70 -> 69.98 | AG14: =AN14*B$67 -> 174.95 | AH14: =AN14*$B$74 -> 69.98 | AI14: =AN14-(AN14/1.18) -> 533.74576 | AJ14: =Z14*5% -> 88.560844 | AK14: =Z14*3% -> 53.136506 | AL14: =AN14-Y14-AD14-AE14-AG14-AI14-AJ14-AK14-AF14-AH14 -> -367.08436 | AM14: =AL14/AN14 -> -0.10491122 | AN14: 3499 | AR14: 6399 | AV14: =SUM(AN14-AI14)-Y14 -> 1464.223 | AW14: =AV14/AN14 -> 0.41846899 | AY14: =Y14/U14 -> 127.20604 | AZ14: =AN14/+SUM(Y14/84) -> 195.80938 | BA14: =AN14/U14 -> 296.52542
F15: FBA75968 | G15: B0BC99CYXD | H15: MB-350 | I15: Gaming | L15: Anji Bitai | M15: Nexlev 350mm Heavy Duty Metal Base | O15: 3.1 | P15: 67 | Q15: 10 | R15: 65 | S15: =(P15*Q15*R15)/1000000 -> 0.04355 | T15: =(P15*Q15*R15)/5000 -> 8.71 | U15: 5.9 | W15: =B$27/(B$28/S15) -> 1.2808824 | X15: =(U15+W15)*(B$30+(B$30*B$45)) -> 1.9747426 | Y15: =(U15+W15+X15)*B$26 -> 824.00625 | Z15: =Y15*1.18 -> 972.32737 | AA15: =AN15*IF(AN15<15001,B$64,B$65) -> 374.85 | AB15: 47 | AC15: 278 | AD15: =AA15+AB15+AC15 -> 699.85 | AE15: =AN15*B$66 -> 374.85 | AF15: =AN15*$B$70 -> 49.98 | AG15: =AN15*B$67 -> 124.95 | AH15: =AN15*$B$74 -> 49.98 | AI15: =AN15-(AN15/1.18) -> 381.20339 | AJ15: =Z15*5% -> 48.616369 | AK15: =Z15*3% -> 29.169821 | AL15: =AN15-Y15-AD15-AE15-AG15-AI15-AJ15-AK15-AF15-AH15 -> -83.60583 | AM15: =AL15/AN15 -> -0.033455714 | AN15: 2499 | AR15: 3999 | AV15: =SUM(AN15-AI15)-Y15 -> 1293.7904 | AW15: =AV15/AN15 -> 0.51772323 | AY15: =Y15/U15 -> 139.66208 | AZ15: =AN15/+SUM(Y15/84) -> 254.75049 | BA15: =AN15/U15 -> 423.55932
F16: FBA75969 | G16: B0BC93RS1L | H16: NB-350 | I16: Gaming | L16: Anji Bitai | M16: Nexlev 350mm Heavy Duty Base | O16: 2.65 | P16: 67 | Q16: 10 | R16: 65 | S16: =(P16*Q16*R16)/1000000 -> 0.04355 | T16: =(P16*Q16*R16)/5000 -> 8.71 | U16: 3.7 | W16: =B$27/(B$28/S16) -> 1.2808824 | X16: =(U16+W16)*(B$30+(B$30*B$45)) -> 1.3697426 | Y16: =(U16+W16+X16)*B$26 -> 571.55625 | Z16: =Y16*1.18 -> 674.43637 | AA16: =AN16*IF(AN16<15001,B$64,B$65) -> 299.85 | AB16: 47 | AC16: 294 | AD16: =AA16+AB16+AC16 -> 640.85 | AE16: =AN16*B$66 -> 299.85 | AF16: =AN16*$B$70 -> 39.98 | AG16: =AN16*B$67 -> 99.95 | AH16: =AN16*$B$74 -> 39.98 | AI16: =AN16-(AN16/1.18) -> 304.9322 | AJ16: =Z16*5% -> 33.721819 | AK16: =Z16*3% -> 20.233091 | AL16: =AN16-Y16-AD16-AE16-AG16-AI16-AJ16-AK16-AF16-AH16 -> -52.053363 | AM16: =AL16/AN16 -> -0.026039702 | AN16: 1999 | AR16: 2499 | AV16: =SUM(AN16-AI16)-Y16 -> 1122.5115 | AW16: =AV16/AN16 -> 0.56153654 | AY16: =Y16/U16 -> 154.47466 | AZ16: =AN16/+SUM(Y16/84) -> 293.78736 | BA16: =AN16/U16 -> 540.27027
F17: FBA75965 | G17: B0BGXYD1ZP | H17: AR-4D | I17: Gaming | L17: Anji Bitai | M17: The 4D Armrest is adjustable in four dimensions. You can adjust them in height, forward/backward position, left/right as well as rotate them around their axis. | O17: 3.5 | P17: 25 | Q17: 29 | R17: 33 | S17: =(P17*Q17*R17)/1000000 -> 0.023925 | T17: =(P17*Q17*R17)/5000 -> 4.785 | U17: 10 | W17: =B$27/(B$28/S17) -> 0.70367647 | X17: =(U17+W17)*(B$30+(B$30*B$45)) -> 2.943511 | Y17: =(U17+W17+X17)*B$26 -> 1228.2469 | Z17: =Y17*1.18 -> 1449.3313 | AA17: =AN17*IF(AN17<15001,B$64,B$65) -> 419.85 | AB17: 47 | AC17: 262 | AD17: =AA17+AB17+AC17 -> 728.85 | AE17: =AN17*B$66 -> 419.85 | AF17: =AN17*$B$70 -> 55.98 | AG17: =AN17*B$67 -> 139.95 | AH17: =AN17*$B$74 -> 55.98 | AI17: =AN17-(AN17/1.18) -> 426.9661 | AJ17: =Z17*5% -> 72.466566 | AK17: =Z17*3% -> 43.479939 | AL17: =AN17-Y17-AD17-AE17-AG17-AI17-AJ17-AK17-AF17-AH17 -> -372.76948 | AM17: =AL17/AN17 -> -0.13317952 | AN17: 2799 | AR17: 5499 | AV17: =SUM(AN17-AI17)-Y17 -> 1143.787 | AW17: =AV17/AN17 -> 0.40864131 | AY17: =Y17/U17 -> 122.82469 | AZ17: =AN17/+SUM(Y17/84) -> 191.42406 | BA17: =AN17/U17 -> 279.9
F18: FBA75966 | G18: B0BGXZB3CM | H18: AR-3D | I18: Gaming | L18: Anji Bitai | M18: 3D Armrests can be adjusted in height, forward/backward position as well as can be rotated around their axis | O18: 2.9 | P18: 25 | Q18: 29 | R18: 33 | S18: =(P18*Q18*R18)/1000000 -> 0.023925 | T18: =(P18*Q18*R18)/5000 -> 4.785 | U18: 7.9 | W18: =B$27/(B$28/S18) -> 0.70367647 | X18: =(U18+W18)*(B$30+(B$30*B$45)) -> 2.366011 | Y18: =(U18+W18+X18)*B$26 -> 987.27187 | Z18: =Y18*1.18 -> 1164.9808 | AA18: =AN18*IF(AN18<15001,B$64,B$65) -> 344.85 | AB18: 47 | AC18: 181.1 | AD18: =AA18+AB18+AC18 -> 572.95 | AE18: =AN18*B$66 -> 344.85 | AF18: =AN18*$B$70 -> 45.98 | AG18: =AN18*B$67 -> 114.95 | AH18: =AN18*$B$74 -> 45.98 | AI18: =AN18-(AN18/1.18) -> 350.69492 | AJ18: =Z18*5% -> 58.249041 | AK18: =Z18*3% -> 34.949424 | AL18: =AN18-Y18-AD18-AE18-AG18-AI18-AJ18-AK18-AF18-AH18 -> -256.87526 | AM18: =AL18/AN18 -> -0.11173347 | AN18: 2299 | AR18: 4599 | AV18: =SUM(AN18-AI18)-Y18 -> 961.03321 | AW18: =AV18/AN18 -> 0.41802227 | AY18: =Y18/U18 -> 124.97112 | AZ18: =AN18/+SUM(Y18/84) -> 195.60569 | BA18: =AN18/U18 -> 291.01266
F19: FBA75973 | G19: B0BGY2XKZ1 | H19: BM-01 | I19: Gaming | L19: Anji Bitai | M19: The butterfly tilt mechanism is actually an office chair tilt mechanism. Because its shape is like a butterfly with outstretched wings. People tend to use the butterfly tilt mechanism as its common name. | O19: 1.75 | P19: 29 | Q19: 23 | R19: 13 | S19: =(P19*Q19*R19)/1000000 -> 0.008671 | T19: =(P19*Q19*R19)/5000 -> 1.7342 | U19: 2.7 | W19: =B$27/(B$28/S19) -> 0.25502941 | X19: =(U19+W19)*(B$30+(B$30*B$45)) -> 0.81263309 | Y19: =(U19+W19+X19)*B$26 -> 339.08963 | Z19: =Y19*1.18 -> 400.12576 | AA19: =AN19*IF(AN19<15001,B$64,B$65) -> 239.85 | AB19: 47 | AC19: 197 | AD19: =AA19+AB19+AC19 -> 483.85 | AE19: =AN19*B$66 -> 239.85 | AF19: =AN19*$B$70 -> 31.98 | AG19: =AN19*B$67 -> 79.95 | AH19: =AN19*$B$74 -> 31.98 | AI19: =AN19-(AN19/1.18) -> 243.91525 | AJ19: =Z19*5% -> 20.006288 | AK19: =Z19*3% -> 12.003773 | AL19: =AN19-Y19-AD19-AE19-AG19-AI19-AJ19-AK19-AF19-AH19 -> 116.37506 | AM19: =AL19/AN19 -> 0.0727799 | AN19: 1599 | AR19: 2199 | AV19: =SUM(AN19-AI19)-Y19 -> 1015.9951 | AW19: =AV19/AN19 -> 0.63539407 | AY19: =Y19/U19 -> 125.58875 | AZ19: =AN19/+SUM(Y19/84) -> 396.10767 | BA19: =AN19/U19 -> 592.22222
F20: FBA75974 | G20: B0BGY4MLKX | H20: FM-01 | I20: Gaming | L20: Anji Bitai | M20: The Frog Tilt Mechanism adjusts the angle of the seat. This reduces the pressure on the lower back, ensures proper posture, and alleviates blood flow to the legs and feet. When a person sits on a chair with a frog mechanism and leans back, his feet will remain on the ground which makes it more comfortable. | O20: 3.9 | P20: 34 | Q20: 27 | R20: 20 | S20: =(P20*Q20*R20)/1000000 -> 0.01836 | T20: =(P20*Q20*R20)/5000 -> 3.672 | U20: 10.4 | W20: =B$27/(B$28/S20) -> 0.54 | X20: =(U20+W20)*(B$30+(B$30*B$45)) -> 3.0085 | Y20: =(U20+W20+X20)*B$26 -> 1255.365 | Z20: =Y20*1.18 -> 1481.3307 | AA20: =AN20*IF(AN20<15001,B$64,B$65) -> 419.85 | AB20: 47 | AC20: 230 | AD20: =AA20+AB20+AC20 -> 696.85 | AE20: =AN20*B$66 -> 419.85 | AF20: =AN20*$B$70 -> 55.98 | AG20: =AN20*B$67 -> 139.95 | AH20: =AN20*$B$74 -> 55.98 | AI20: =AN20-(AN20/1.18) -> 426.9661 | AJ20: =Z20*5% -> 74.066535 | AK20: =Z20*3% -> 44.439921 | AL20: =AN20-Y20-AD20-AE20-AG20-AI20-AJ20-AK20-AF20-AH20 -> -370.44756 | AM20: =AL20/AN20 -> -0.13234997 | AN20: 2799 | AR20: 5699 | AV20: =SUM(AN20-AI20)-Y20 -> 1116.6689 | AW20: =AV20/AN20 -> 0.3989528 | AY20: =Y20/U20 -> 120.70817 | AZ20: =AN20/+SUM(Y20/84) -> 187.28896 | BA20: =AN20/U20 -> 269.13462
F21: FBA75971 | G21: B0BGY3223L | H21: RC-75 | I21: Gaming | L21: Anji Bitai | M21: 75mm Racing Caster Wheels | O21: 1.15 | P21: 8 | Q21: 8 | R21: 27 | S21: =(P21*Q21*R21)/1000000 -> 0.001728 | T21: =(P21*Q21*R21)/5000 -> 0.3456 | U21: 3.6 | W21: =B$27/(B$28/S21) -> 0.050823529 | X21: =(U21+W21)*(B$30+(B$30*B$45)) -> 1.0039765 | Y21: =(U21+W21+X21)*B$26 -> 418.932 | Z21: =Y21*1.18 -> 494.33976 | AA21: =AN21*IF(AN21<15001,B$64,B$65) -> 164.85 | AB21: 47 | AC21: 131 | AD21: =AA21+AB21+AC21 -> 342.85 | AE21: =AN21*B$66 -> 164.85 | AF21: =AN21*$B$70 -> 21.98 | AG21: =AN21*B$67 -> 54.95 | AH21: =AN21*$B$74 -> 21.98 | AI21: =AN21-(AN21/1.18) -> 167.64407 | AJ21: =Z21*5% -> 24.716988 | AK21: =Z21*3% -> 14.830193 | AL21: =AN21-Y21-AD21-AE21-AG21-AI21-AJ21-AK21-AF21-AH21 -> -133.73325 | AM21: =AL21/AN21 -> -0.1216863 | AN21: 1099 | AR21: 2499 | AV21: =SUM(AN21-AI21)-Y21 -> 512.42393 | AW21: =AV21/AN21 -> 0.46626381 | AY21: =Y21/U21 -> 116.37 | AZ21: =AN21/+SUM(Y21/84) -> 220.36034 | BA21: =AN21/U21 -> 305.27778
F22: FBA75972 | G22: B0BGY61JMN | H22: RB-75 | I22: Gaming | L22: Anji Bitai | M22: In-Line Rollerblade Casters for Chair | O22: 1.25 | P22: 8 | Q22: 8 | R22: 27 | S22: =(P22*Q22*R22)/1000000 -> 0.001728 | T22: =(P22*Q22*R22)/5000 -> 0.3456 | U22: 6.5 | W22: =B$27/(B$28/S22) -> 0.050823529 | X22: =(U22+W22)*(B$30+(B$30*B$45)) -> 1.8014765 | Y22: =(U22+W22+X22)*B$26 -> 751.707 | Z22: =Y22*1.18 -> 887.01426 | AA22: =AN22*IF(AN22<15001,B$64,B$65) -> 239.85 | AB22: 47 | AC22: 131 | AD22: =AA22+AB22+AC22 -> 417.85 | AE22: =AN22*B$66 -> 239.85 | AF22: =AN22*$B$70 -> 31.98 | AG22: =AN22*B$67 -> 79.95 | AH22: =AN22*$B$74 -> 31.98 | AI22: =AN22-(AN22/1.18) -> 243.91525 | AJ22: =Z22*5% -> 44.350713 | AK22: =Z22*3% -> 26.610428 | AL22: =AN22-Y22-AD22-AE22-AG22-AI22-AJ22-AK22-AF22-AH22 -> -269.1934 | AM22: =AL22/AN22 -> -0.16835109 | AN22: 1599 | AR22: 3999 | AV22: =SUM(AN22-AI22)-Y22 -> 603.37775 | AW22: =AV22/AN22 -> 0.37734693 | AY22: =Y22/U22 -> 115.64723 | AZ22: =AN22/+SUM(Y22/84) -> 178.68132 | BA22: =AN22/U22 -> 246
F23: FBA75970 | G23: B0BGY6R2YQ | H23: NC-60 | I23: Gaming | L23: Anji Bitai | M23: 60mm Nylon Caster Wheels | O23: 0.65 | P23: 8 | Q23: 8 | R23: 27 | S23: =(P23*Q23*R23)/1000000 -> 0.001728 | T23: =(P23*Q23*R23)/5000 -> 0.3456 | U23: 1.3 | W23: =B$27/(B$28/S23) -> 0.050823529 | X23: =(U23+W23)*(B$30+(B$30*B$45)) -> 0.37147647 | Y23: =(U23+W23+X23)*B$26 -> 155.007 | Z23: =Y23*1.18 -> 182.90826 | AA23: =AN23*IF(AN23<15001,B$64,B$65) -> 104.85 | AB23: 47 | AC23: 98 | AD23: =AA23+AB23+AC23 -> 249.85 | AE23: =AN23*B$66 -> 104.85 | AF23: =AN23*$B$70 -> 13.98 | AG23: =AN23*B$67 -> 34.95 | AH23: =AN23*$B$74 -> 13.98 | AI23: =AN23-(AN23/1.18) -> 106.62712 | AJ23: =Z23*5% -> 9.145413 | AK23: =Z23*3% -> 5.4872478 | AL23: =AN23-Y23-AD23-AE23-AG23-AI23-AJ23-AK23-AF23-AH23 -> 5.1232206 | AM23: =AL23/AN23 -> 0.007329357 | AN23: 699 | AR23: 1499 | AV23: =SUM(AN23-AI23)-Y23 -> 437.36588 | AW23: =AV23/AN23 -> 0.62570226 | AY23: =Y23/U23 -> 119.23615 | AZ23: =AN23/+SUM(Y23/84) -> 378.7958 | BA23: =AN23/U23 -> 537.69231
F24: FBA76595 | G24: #N/A | H24: GL-80 | I24: Gaming | L24: ROTVAC ENTERPRISE | M24: 80mm Class 4 Gaslift | O24: 0.8 | P24: 6 | Q24: 6 | R24: 30 | S24: =(P24*Q24*R24)/1000000 -> 0.00108 | T24: =(P24*Q24*R24)/5000 -> 0.216 | U24: 2.4 | W24: =B$27/(B$28/S24) -> 0.031764706 | X24: =(U24+W24)*(B$30+(B$30*B$45)) -> 0.66873529 | Y24: =(U24+W24+X24)*B$26 -> 279.045 | Z24: =Y24*1.18 -> 329.2731 | AA24: =AN24*IF(AN24<15001,B$64,B$65) -> 119.85 | AB24: 47 | AC24: 125 | AD24: =AA24+AB24+AC24 -> 291.85 | AE24: =AN24*B$66 -> 119.85 | AF24: =AN24*$B$70 -> 15.98 | AG24: =AN24*B$67 -> 39.95 | AH24: =AN24*$B$74 -> 15.98 | AI24: =AN24-(AN24/1.18) -> 121.88136 | AJ24: =Z24*5% -> 16.463655 | AK24: =Z24*3% -> 9.878193 | AL24: =AN24-Y24-AD24-AE24-AG24-AI24-AJ24-AK24-AF24-AH24 -> -111.8782 | AM24: =AL24/AN24 -> -0.14002278 | AN24: 799 | AV24: =SUM(AN24-AI24)-Y24 -> 398.07364 | AW24: =AV24/AN24 -> 0.49821482 | AY24: =Y24/U24 -> 116.26875 | AZ24: =AN24/+SUM(Y24/84) -> 240.52035 | BA24: =AN24/U24 -> 332.91667
F25: FBA78979 | G25: B0CDPQXPC1 | H25: GS-01 | I25: Home & Kitchen | J25: Fabric Care | K25: QH09 | L25: Zhejiang Huaguang | M25: Nexlev Premium Garment Steamer-Mist | N25: 85167990 | O25: 1.3 | P25: 29.2 | Q25: 22.4 | R25: 13.6 | S25: =(P25*Q25*R25)/1000000 -> 0.008895488 | T25: =(P25*Q25*R25)/5000 -> 1.7790976 | U25: 11.68 | V25: 11.68 | W25: =B$27/(B$28/S25) -> 0.261632 | X25: =(U25+W25)*(B$31+(B$31*B$45)) -> 2.627159 | Y25: =(U25+W25+X25)*B$26 -> 1311.1912 | Z25: =Y25*1.18 -> 1547.2056 | AA25: =AN25*4.5% -> 103.455 | AB25: 51 | AC25: 115 | AD25: =AA25+AB25+AC25 -> 269.455 | AE25: =AN25*B$66 -> 344.85 | AF25: =AN25*$B$70 -> 45.98 | AG25: =AN25*B$67 -> 114.95 | AH25: =AN25*$B$74 -> 45.98 | AI25: =AN25-(AN25/1.18) -> 350.69492 | AJ25: =Z25*5% -> 77.36028 | AK25: =Z25*3% -> 46.416168 | AL25: =AN25-Y25-AD25-AE25-AG25-AI25-AJ25-AK25-AF25-AH25 -> -307.87756 | AM25: =AL25/AN25 -> -0.13391803 | AN25: 2299 | AP25: 2349 | AR25: 5999 | AV25: =SUM(AN25-AI25)-Y25 -> 637.11389 | AW25: =AV25/AN25 -> 0.27712653 | AX25: 8904422503366 | AY25: =Y25/U25 -> 112.25952 | AZ25: =AN25/+SUM(Y25/84) -> 147.28287 | BA25: =AN25/U25 -> 196.83219
A26: Dollar Conversion Rate | B26: 90 | F26: FBA78980 | G26: B0CDPMX152 | H26: GS-02 | I26: Home & Kitchen | J26: Fabric Care | K26: QH09E | L26: Zhejiang Huaguang | M26: Nexlev Garment Steamer - Swift | N26: 85167990 | O26: 1.3 | P26: 29.2 | Q26: 22.4 | R26: 13.6 | S26: =(P26*Q26*R26)/1000000 -> 0.008895488 | T26: =(P26*Q26*R26)/5000 -> 1.7790976 | U26: 9.45 | V26: 9.45 | W26: =B$27/(B$28/S26) -> 0.261632 | X26: =(U26+W26)*(B$31+(B$31*B$45)) -> 2.136559 | Y26: =(U26+W26+X26)*B$26 -> 1066.3372 | Z26: =Y26*1.18 -> 1258.2779 | AA26: =AN26*4.5% -> 92.25 | AB26: 51 | AC26: 115 | AD26: =AA26+AB26+AC26 -> 258.25 | AE26: =AN26*B$66 -> 307.5 | AF26: =AN26*$B$70 -> 41 | AG26: =AN26*B$67 -> 102.5 | AH26: =AN26*$B$74 -> 41 | AI26: =AN26-(AN26/1.18) -> 312.71186 | AJ26: =Z26*5% -> 62.913894 | AK26: =Z26*3% -> 37.748337 | AL26: =AN26-Y26-AD26-AE26-AG26-AI26-AJ26-AK26-AF26-AH26 -> -179.96129 | AM26: =AL26/AN26 -> -0.087785995 | AN26: 2050 | AP26: 2049 | AR26: 4999 | AV26: =SUM(AN26-AI26)-Y26 -> 670.95094 | AW26: =AV26/AN26 -> 0.32729314 | AX26: 8904422503373 | AY26: =Y26/U26 -> 112.83991 | AZ26: =AN26/+SUM(Y26/84) -> 161.48738 | BA26: =AN26/U26 -> 216.93122
A27: 40HQ Freight+Clearance | B27: 2000 | F27: FBA78981 | G27: B0CDPP45BM | H27: SC-01 | I27: Home & Kitchen | J27: Cleaning & Vacumming | K27: C5 | L27: Zhejiang Huaguang | M27: Nexlev Steam Cleaner | N27: 85098000 | O27: 2.1 | P27: 30 | Q27: 19.5 | R27: 21 | S27: =(P27*Q27*R27)/1000000 -> 0.012285 | T27: =(P27*Q27*R27)/5000 -> 2.457 | U27: 13.5 | V27: 13.4 | W27: =B$27/(B$28/S27) -> 0.36132353 | X27: =(U27+W27)*(B$31+(B$31*B$45)) -> 3.0494912 | Y27: =(U27+W27+X27)*B$26 -> 1521.9733 | Z27: =Y27*1.18 -> 1795.9285 | AA27: =AN27*4.5% -> 161.955 | AB27: 51 | AC27: 148 | AD27: =AA27+AB27+AC27 -> 360.955 | AE27: =AN27*B$66 -> 539.85 | AF27: =AN27*$B$70 -> 71.98 | AG27: =AN27*B$67 -> 179.95 | AH27: =AN27*$B$74 -> 71.98 | AI27: =AN27-(AN27/1.18) -> 549 | AJ27: =Z27*5% -> 89.796426 | AK27: =Z27*3% -> 53.877856 | AL27: =SUM(AN27-AI27)-Y27-AD27-AE27-AG27-AJ27-AK27-AF27-AH27 -> 159.63739 | AM27: =AL27/SUM(AN27-AI27) -> 0.052340129 | AN27: 3599 | AP27: 3299 | AR27: 9999 | AV27: =SUM(AN27-AI27)-Y27 -> 1528.0267 | AW27: =AV27/AN27 -> 0.42456979 | AX27: 8904422503380 | AY27: =Y27/U27 -> 112.73876 | AZ27: =AN27/+SUM(Y27/84) -> 198.63423 | BA27: =AN27/U27 -> 266.59259
A28: 40HQ Usable CBM | B28: 68 | F28: FBA78994 | G28: B0CDQ98FDM | H28: NP-01 | I28: Sports, Fitness & Outdoors | J28: Travel Accessories | L28: Guangzhou Jibei | M28: Neck Pillow with Memory Foam and Striped Texture | N28: 94043090 | O28: 0.3 | P28: 21.6 | Q28: 16.6 | R28: 13.9 | S28: =(P28*Q28*R28)/1000000 -> 0.004983984 | T28: =(P28*Q28*R28)/5000 -> 0.9967968 | U28: 2.95 | W28: =B$27/(B$28/S28) -> 0.14658776 | X28: =(U28+W28)*(B$30+(B$30*B$45)) -> 0.85156164 | Y28: =(U28+W28+X28)*B$26 -> 355.33345 | Z28: =Y28*1.12 -> 397.97346 | AA28: =AN28*10% -> 69.9 | AB28: 26 | AC28: 77 | AD28: =AA28+AB28+AC28 -> 172.9 | AE28: =AN28*B$66 -> 104.85 | AF28: =AN28*$B$70 -> 13.98 | AG28: =AN28*B$67 -> 34.95 | AH28: =AN28*$B$74 -> 13.98 | AI28: =AN28-(AN28/1.12) -> 74.892857 | AJ28: =Z28*5% -> 19.898673 | AK28: =Z28*3% -> 11.939204 | AL28: =AN28-Y28-AD28-AE28-AG28-AI28-AJ28-AK28-AF28-AH28 -> -103.72418 | AM28: =AL28/AN28 -> -0.14838938 | AN28: 699 | AP28: 679 | AR28: 1499 | AV28: =SUM(AN28-AI28)-Y28 -> 268.7737 | AW28: =AV28/AN28 -> 0.38451173 | AX28: 8904422503496 | AY28: =Y28/U28 -> 120.45202 | AZ28: =AN28/+SUM(Y28/84) -> 165.24197 | BA28: =AN28/U28 -> 236.94915
A29: Fulfillment Rate/kg | B29: 40 | F29: FBA78995 | G29: B0CDQ55W2M | H29: NP-02 | I29: Sports, Fitness & Outdoors | J29: Travel Accessories | L29: Guangzhou Jibei | M29: Neck Pillow with Memory Foam (Dark Grey) | N29: 94043090 | O29: 0.3 | P29: 21.6 | Q29: 16.6 | R29: 13.9 | S29: =(P29*Q29*R29)/1000000 -> 0.004983984 | T29: =(P29*Q29*R29)/5000 -> 0.9967968 | U29: 2.95 | W29: =B$27/(B$28/S29) -> 0.14658776 | X29: =(U29+W29)*(B$30+(B$30*B$45)) -> 0.85156164 | Y29: =(U29+W29+X29)*B$26 -> 355.33345 | Z29: =Y29*1.12 -> 397.97346 | AA29: =AN29*10% -> 69.9 | AB29: 25 | AC29: 78 | AD29: =AA29+AB29+AC29 -> 172.9 | AE29: =AN29*B$66 -> 104.85 | AF29: =AN29*$B$70 -> 13.98 | AG29: =AN29*B$67 -> 34.95 | AH29: =AN29*$B$74 -> 13.98 | AI29: =AN29-(AN29/1.12) -> 74.892857 | AJ29: =Z29*5% -> 19.898673 | AK29: =Z29*3% -> 11.939204 | AL29: =AN29-Y29-AD29-AE29-AG29-AI29-AJ29-AK29-AF29-AH29 -> -103.72418 | AM29: =AL29/AN29 -> -0.14838938 | AN29: 699 | AP29: 679 | AR29: 1999 | AV29: =SUM(AN29-AI29)-Y29 -> 268.7737 | AW29: =AV29/AN29 -> 0.38451173 | AX29: 8904422503502 | AY29: =Y29/U29 -> 120.45202 | AZ29: =AN29/+SUM(Y29/84) -> 165.24197 | BA29: =AN29/U29 -> 236.94915
A30: Duty - Furniture | B30: 0.25 | F30: FBA78996 | G30: B0CDQ6G4TC | H30: NP-03 | I30: Sports, Fitness & Outdoors | J30: Travel Accessories | K30: W | L30: Guangzhou Jibei | M30: Neck Pillow with Memory Foam (Grey) | N30: 94043090 | O30: 0.3 | P30: 21.6 | Q30: 16.6 | R30: 13.9 | S30: =(P30*Q30*R30)/1000000 -> 0.004983984 | T30: =(P30*Q30*R30)/5000 -> 0.9967968 | U30: 2.95 | W30: =B$27/(B$28/S30) -> 0.14658776 | X30: =(U30+W30)*(B$30+(B$30*B$45)) -> 0.85156164 | Y30: =(U30+W30+X30)*B$26 -> 355.33345 | Z30: =Y30*1.12 -> 397.97346 | AA30: =AN30*10% -> 69.9 | AB30: 25 | AC30: 78 | AD30: =AA30+AB30+AC30 -> 172.9 | AE30: =AN30*B$66 -> 104.85 | AI30: =AN30-(AN30/1.12) -> 74.892857 | AL30: =AN30-Y30-AD30-AE30-AG30-AI30-AJ30-AK30-AF30-AH30 -> -8.9763031 | AM30: =AL30/AN30 -> -0.012841635 | AN30: 699 | AP30: 679 | AR30: 1499 | AV30: =SUM(AN30-AI30)-Y30 -> 268.7737 | AW30: =AV30/AN30 -> 0.38451173 | AX30: 8904422503519 | AY30: =Y30/U30 -> 120.45202 | AZ30: =AN30/+SUM(Y30/84) -> 165.24197 | BA30: =AN30/U30 -> 236.94915
A31: Duty - Small Appliances | B31: 0.2 | F31: FBA78997 | G31: B0CDQ5Y3YB | H31: NP-04 | I31: Sports, Fitness & Outdoors | J31: Travel Accessories | L31: Guangzhou Jibei | M31: Neck Pillow with Memory Foam (Blue) | N31: 94043090 | O31: 0.3 | P31: 21.6 | Q31: 16.6 | R31: 13.9 | S31: =(P31*Q31*R31)/1000000 -> 0.004983984 | T31: =(P31*Q31*R31)/5000 -> 0.9967968 | U31: 2.95 | W31: =B$27/(B$28/S31) -> 0.14658776 | X31: =(U31+W31)*(B$30+(B$30*B$45)) -> 0.85156164 | Y31: =(U31+W31+X31)*B$26 -> 355.33345 | Z31: =Y31*1.12 -> 397.97346 | AA31: =AN31*10% -> 79.9 | AB31: 25 | AC31: 78 | AD31: =AA31+AB31+AC31 -> 182.9 | AE31: =AN31*B$66 -> 119.85 | AF31: =AN31*$B$70 -> 15.98 | AG31: =AN31*B$67 -> 39.95 | AH31: =AN31*$B$74 -> 15.98 | AI31: =AN31-(AN31/1.12) -> 85.607143 | AJ31: =Z31*5% -> 19.898673 | AK31: =Z31*3% -> 11.939204 | AL31: =AN31-Y31-AD31-AE31-AG31-AI31-AJ31-AK31-AF31-AH31 -> -48.438466 | AM31: =AL31/AN31 -> -0.060623862 | AN31: 799 | AP31: 679 | AR31: 1499 | AV31: =SUM(AN31-AI31)-Y31 -> 358.05941 | AW31: =AV31/AN31 -> 0.44813443 | AX31: 8904422503526 | AY31: =Y31/U31 -> 120.45202 | AZ31: =AN31/+SUM(Y31/84) -> 188.88174 | BA31: =AN31/U31 -> 270.84746
F32: FBA78998 | G32: B0CDQ5NBH8 | H32: NP-05 | I32: Sports, Fitness & Outdoors | J32: Travel Accessories | L32: Guangzhou Jibei | M32: Neck Pillow with Memory Foam (Pink) | N32: 94043090 | O32: 0.3 | P32: 21.6 | Q32: 16.6 | R32: 13.9 | S32: =(P32*Q32*R32)/1000000 -> 0.004983984 | T32: =(P32*Q32*R32)/5000 -> 0.9967968 | U32: 3.925 | W32: =B$27/(B$28/S32) -> 0.14658776 | X32: =(U32+W32)*(B$30+(B$30*B$45)) -> 1.1196866 | Y32: =(U32+W32+X32)*B$26 -> 467.2147 | Z32: =Y32*1.12 -> 523.28046 | AA32: =AN32*10% -> 59.9 | AB32: 25 | AC32: 78 | AD32: =AA32+AB32+AC32 -> 162.9 | AE32: =AN32*B$66 -> 89.85 | AF32: =AN32*$B$70 -> 11.98 | AG32: =AN32*B$67 -> 29.95 | AH32: =AN32*$B$74 -> 11.98 | AI32: =AN32-(AN32/1.12) -> 64.178571 | AJ32: =Z32*5% -> 26.164023 | AK32: =Z32*3% -> 15.698414 | AL32: =AN32-Y32-AD32-AE32-AG32-AI32-AJ32-AK32-AF32-AH32 -> -280.9157 | AM32: =AL32/AN32 -> -0.46897446 | AN32: 599 | AR32: 1999 | AV32: =SUM(AN32-AI32)-Y32 -> 67.606733 | AW32: =AV32/AN32 -> 0.112866 | AX32: 8904422503533 | AY32: =Y32/U32 -> 119.03559 | AZ32: =AN32/+SUM(Y32/84) -> 107.69353 | BA32: =AN32/U32 -> 152.61146
F33: FBA78999 | G33: B0CFFQK45G | H33: TR-01 | I33: Sports, Fitness & Outdoors | J33: Travel Accessories | L33: D&H Textile | M33: Nexlev Travel Blanket 50x60" (Black) | N33: 63013000 | O33: 0.54 | P33: 43 | Q33: 15.4 | R33: 13.5 | S33: =(P33*Q33*R33)/1000000 -> 0.0089397 | T33: =(P33*Q33*R33)/5000 -> 1.78794 | U33: 3.93 | W33: =B$27/(B$28/S33) -> 0.26293235 | X33: =(U33+W33)*(B$42+(B$42*B$45)) -> 0.46122256 | Y33: =(U33+W33+X33)*B$26 -> 418.87394 | Z33: =Y33*1.18 -> 494.27125 | AA33: =AN33*9.5% -> 85.405 | AB33: 25 | AC33: 107 | AD33: =AA33+AB33+AC33 -> 217.405 | AE33: =AN33*B$66 -> 134.85 | AF33: =AN33*$B$70 -> 17.98 | AG33: =AN33*B$67 -> 44.95 | AH33: =AN33*$B$74 -> 17.98 | AI33: =AN33-(AN33/1.12) -> 96.321429 | AJ33: =Z33*5% -> 24.713563 | AK33: =Z33*3% -> 14.828138 | AL33: =AN33-Y33-AD33-AE33-AG33-AI33-AJ33-AK33-AF33-AH33 -> -88.902071 | AM33: =AL33/AN33 -> -0.098889956 | AN33: 899 | AR33: 2199 | AV33: =SUM(AN33-AI33)-Y33 -> 383.80463 | AW33: =AV33/AN33 -> 0.42692395 | AX33: 8904422503540 | AY33: =Y33/U33 -> 106.5837 | AZ33: =AN33/+SUM(Y33/84) -> 180.28336 | BA33: =AN33/U33 -> 228.75318
F34: FBA79000 | G34: B0CFH2B2MV | H34: TR-02 | I34: Sports, Fitness & Outdoors | J34: Travel Accessories | L34: D&H Textile | M34: Nexlev Travel Blanket 50x60" (Navy) | N34: 63013000 | O34: 0.54 | P34: 43 | Q34: 15.4 | R34: 13.5 | S34: =(P34*Q34*R34)/1000000 -> 0.0089397 | T34: =(P34*Q34*R34)/5000 -> 1.78794 | U34: 3.98 | W34: =B$27/(B$28/S34) -> 0.26293235 | X34: =(U34+W34)*(B$42+(B$42*B$45)) -> 0.46672256 | Y34: =(U34+W34+X34)*B$26 -> 423.86894 | Z34: =Y34*1.18 -> 500.16535 | AA34: =AN34*9.5% -> 85.405 | AB34: 25 | AC34: 107 | AD34: =AA34+AB34+AC34 -> 217.405 | AE34: =AN34*B$66 -> 134.85 | AF34: =AN34*$B$70 -> 17.98 | AG34: =AN34*B$67 -> 44.95 | AH34: =AN34*$B$74 -> 17.98 | AI34: =AN34-(AN34/1.12) -> 96.321429 | AJ34: =Z34*5% -> 25.008268 | AK34: =Z34*3% -> 15.004961 | AL34: =AN34-Y34-AD34-AE34-AG34-AI34-AJ34-AK34-AF34-AH34 -> -94.368599 | AM34: =AL34/AN34 -> -0.10497063 | AN34: 899 | AR34: 2199 | AV34: =SUM(AN34-AI34)-Y34 -> 378.80963 | AW34: =AV34/AN34 -> 0.42136777 | AX34: 8904422503557 | AY34: =Y34/U34 -> 106.49973 | AZ34: =AN34/+SUM(Y34/84) -> 178.15884 | BA34: =AN34/U34 -> 225.8794
F35: FBA79001 | G35: B0CFH2C369 | H35: TR-03 | I35: Sports, Fitness & Outdoors | J35: Travel Accessories | L35: D&H Textile | M35: Nexlev Travel Blanket 50x60" (Pink) | N35: 63013000 | O35: 0.54 | P35: 43 | Q35: 15.4 | R35: 13.5 | S35: =(P35*Q35*R35)/1000000 -> 0.0089397 | T35: =(P35*Q35*R35)/5000 -> 1.78794 | U35: 3.98 | W35: =B$27/(B$28/S35) -> 0.26293235 | X35: =(U35+W35)*(B$42+(B$42*B$45)) -> 0.46672256 | Y35: =(U35+W35+X35)*B$26 -> 423.86894 | Z35: =Y35*1.18 -> 500.16535 | AA35: =AN35*9.5% -> 85.405 | AB35: 25 | AC35: 107 | AD35: =AA35+AB35+AC35 -> 217.405 | AE35: =AN35*B$66 -> 134.85 | AF35: =AN35*$B$70 -> 17.98 | AG35: =AN35*B$67 -> 44.95 | AH35: =AN35*$B$74 -> 17.98 | AI35: =AN35-(AN35/1.12) -> 96.321429 | AJ35: =Z35*5% -> 25.008268 | AK35: =Z35*3% -> 15.004961 | AL35: =AN35-Y35-AD35-AE35-AG35-AI35-AJ35-AK35-AF35-AH35 -> -94.368599 | AM35: =AL35/AN35 -> -0.10497063 | AN35: 899 | AR35: 2199 | AV35: =SUM(AN35-AI35)-Y35 -> 378.80963 | AW35: =AV35/AN35 -> 0.42136777 | AX35: 8904422503564 | AY35: =Y35/U35 -> 106.49973 | AZ35: =AN35/+SUM(Y35/84) -> 178.15884 | BA35: =AN35/U35 -> 225.8794
F36: FBA79002 | G36: B0CFH5R7Y7 | H36: TR-04 | I36: Sports, Fitness & Outdoors | J36: Travel Accessories | L36: D&H Textile | M36: Nexlev Travel Blanket 50x60" (Grey) | N36: 63013000 | O36: 0.54 | P36: 43 | Q36: 15.4 | R36: 13.5 | S36: =(P36*Q36*R36)/1000000 -> 0.0089397 | T36: =(P36*Q36*R36)/5000 -> 1.78794 | U36: 3.98 | W36: =B$27/(B$28/S36) -> 0.26293235 | X36: =(U36+W36)*(B$42+(B$42*B$45)) -> 0.46672256 | Y36: =(U36+W36+X36)*B$26 -> 423.86894 | Z36: =Y36*1.18 -> 500.16535 | AA36: =AN36*9.5% -> 85.405 | AB36: 25 | AC36: 135 | AD36: =AA36+AB36+AC36 -> 245.405 | AE36: =AN36*B$66 -> 134.85 | AF36: =AN36*$B$70 -> 17.98 | AG36: =AN36*B$67 -> 44.95 | AH36: =AN36*$B$74 -> 17.98 | AI36: =AN36-(AN36/1.12) -> 96.321429 | AJ36: =Z36*5% -> 25.008268 | AK36: =Z36*3% -> 15.004961 | AL36: =AN36-Y36-AD36-AE36-AG36-AI36-AJ36-AK36-AF36-AH36 -> -122.3686 | AM36: =AL36/AN36 -> -0.13611635 | AN36: 899 | AR36: 2199 | AV36: =SUM(AN36-AI36)-Y36 -> 378.80963 | AW36: =AV36/AN36 -> 0.42136777 | AX36: 8904422503571 | AY36: =Y36/U36 -> 106.49973 | AZ36: =AN36/+SUM(Y36/84) -> 178.15884 | BA36: =AN36/U36 -> 225.8794
F37: FBA79003 | G37: B0CFH6C6YM | H37: TR-05 | I37: Sports, Fitness & Outdoors | J37: Travel Accessories | L37: D&H Textile | M37: Nexlev Waterproof Picnic Blanket 40x65" (Grey) | N37: 63013000 | O37: 1.25 | P37: 43 | Q37: 15.4 | R37: 13.5 | S37: =(P37*Q37*R37)/1000000 -> 0.0089397 | T37: =(P37*Q37*R37)/5000 -> 1.78794 | U37: 5.45 | W37: =B$27/(B$28/S37) -> 0.26293235 | X37: =(U37+W37)*(B$42+(B$42*B$45)) -> 0.62842256 | Y37: =(U37+W37+X37)*B$26 -> 570.72194 | Z37: =Y37*1.18 -> 673.45189 | AA37: =AN37*9.5% -> 83.505 | AB37: 25 | AC37: 135 | AD37: =AA37+AB37+AC37 -> 243.505 | AE37: =AN37*B$66 -> 131.85 | AF37: =AN37*$B$70 -> 17.58 | AG37: =AN37*B$67 -> 43.95 | AH37: =AN37*$B$74 -> 17.58 | AI37: =AN37-(AN37/1.12) -> 94.178571 | AJ37: =Z37*5% -> 33.672595 | AK37: =Z37*3% -> 20.203557 | AL37: =AN37-Y37-AD37-AE37-AG37-AI37-AJ37-AK37-AF37-AH37 -> -294.24166 | AM37: =AL37/AN37 -> -0.33474592 | AN37: 879 | AR37: 2999 | AV37: =SUM(AN37-AI37)-Y37 -> 214.09949 | AW37: =AV37/AN37 -> 0.24357166 | AX37: 8904422503588 | AY37: =Y37/U37 -> 104.71962 | AZ37: =AN37/+SUM(Y37/84) -> 129.37298 | BA37: =AN37/U37 -> 161.2844
F38: FBA79217 | G38: B0C7GMKPP3 | H38: WF100Wh-Light | I38: Pet Supplies | J38: Pet Supplies | L38: Molly Tan | M38: NexLev Pet Water Fountain 2L | N38: 84212190 | O38: 0.62 | P38: 16.5 | Q38: 16.5 | R38: 15.5 | S38: =(P38*Q38*R38)/1000000 -> 0.004219875 | T38: =(P38*Q38*R38)/5000 -> 0.843975 | U38: 4.77 | W38: =B$27/(B$28/S38) -> 0.12411397 | X38: =(U38+W38)*(B$44+(B44*B$45)) -> 0.4037644 | Y38: =(U38+W38+X38)*B$26 -> 476.80905 | Z38: =Y38*1.18 -> 562.63468 | AA38: =AN38*12% -> 167.88 | AB38: 47 | AC38: 107 | AD38: =AA38+AB38+AC38 -> 321.88 | AE38: =AN38*B$66 -> 209.85 | AF38: =AN38*$B$70 -> 27.98 | AG38: =AN38*B$67 -> 69.95 | AH38: =AN38*$B$74 -> 27.98 | AI38: =AN38-(AN38/1.12) -> 149.89286 | AJ38: =Z38*5% -> 28.131734 | AK38: =Z38*3% -> 16.87904 | AL38: =AN38-Y38-AD38-AE38-AG38-AI38-AJ38-AK38-AF38-AH38 -> 69.647315 | AM38: =AL38/AN38 -> 0.049783642 | AN38: 1399 | AR38: 2999 | AV38: =SUM(AN38-AI38)-Y38 -> 772.29809 | AW38: =AV38/AN38 -> 0.5520358 | AY38: =Y38/U38 -> 99.959969 | AZ38: =AN38/+SUM(Y38/84) -> 246.46344 | BA38: =AN38/U38 -> 293.2914
F39: FBA79218 | G39: B0CQ2RKB68 | H39: WF100BL-Light | I39: Pet Supplies | J39: Pet Supplies | L39: Molly Tan | M39: Pet Water Fountain WF100BL with Light without Adapter | N39: 84212190 | O39: 0.62 | P39: 16.5 | Q39: 16.5 | R39: 15.5 | S39: =(P39*Q39*R39)/1000000 -> 0.004219875 | T39: =(P39*Q39*R39)/5000 -> 0.843975 | U39: 8.99 | W39: =B$27/(B$28/S39) -> 0.12411397 | X39: =(U39+W39)*(B$44+(B45*B$45)) -> 0.77469969 | Y39: =(U39+W39+X39)*B$26 -> 889.99323 | Z39: =Y39*1.18 -> 1050.192 | AA39: =AN39*12% -> 227.88 | AB39: 47 | AC39: 107 | AD39: =AA39+AB39+AC39 -> 381.88 | AE39: =AN39*B$66 -> 284.85 | AF39: =AN39*$B$70 -> 37.98 | AG39: =AN39*B$67 -> 94.95 | AH39: =AN39*$B$74 -> 37.98 | AI39: =AN39-(AN39/1.12) -> 203.46429 | AJ39: =Z39*5% -> 52.509601 | AK39: =Z39*3% -> 31.50576 | AL39: =AN39-Y39-AD39-AE39-AG39-AI39-AJ39-AK39-AF39-AH39 -> -116.11288 | AM39: =AL39/AN39 -> -0.061144221 | AN39: 1899 | AR39: 2999 | AV39: =SUM(AN39-AI39)-Y39 -> 805.54249 | AW39: =AV39/AN39 -> 0.42419299 | AY39: =Y39/U39 -> 98.998135 | AZ39: =AN39/+SUM(Y39/84) -> 179.23282 | BA39: =AN39/U39 -> 211.23471
F40: FBA79174 | G40: B0CW1JJP9S | H40: DF-01-BK | I40: HPC | J40: Oral Care | K40: Y820 | L40: Shenzhen Yuxinyuan Electronic Technology Co., Ltd. | M40: Nexlev Dental Flosser (Black) | N40: 84244900 | O40: 0.38 | P40: 23.5 | Q40: 8.7 | R40: 7.5 | S40: =(P40*Q40*R40)/1000000 -> 0.001533375 | T40: =(P40*Q40*R40)/5000 -> 0.306675 | U40: 9.17 | W40: =U40*2% -> 0.1834 | X40: =(U40+W40)*(B$43+(B$43*B$45)) -> 0.7716555 | Y40: =(U40+W40+X40)*B$26 -> 911.255 | Z40: =Y40*1.18 -> 1075.2809 | AA40: =AN40*7.5% -> 98.925 | AB40: 51 | AC40: 59 | AD40: =AA40+AB40+AC40 -> 208.925 | AE40: =AN40*B$72 -> 263.8 | AG40: =AN40*B$67 -> 65.95 | AI40: =AN40-(AN40/1.18) -> 201.20339 | AJ40: =Z40*5% -> 53.764045 | AK40: =Z40*3% -> 32.258427 | AL40: =AN40-Y40-AD40-AE40-AG40-AI40-AJ40-AK40-AF40-AH40 -> -418.15586 | AM40: =AL40/AN40 -> -0.31702491 | AN40: 1319 | AP40: 1580 | AR40: 3599 | AV40: =SUM(AN40-AI40)-Y40 -> 206.54162 | AW40: =AV40/AN40 -> 0.15658955 | AX40: 8904422503854 | AY40: =Y40/U40 -> 99.3735 | AZ40: =AN40/+SUM(Y40/84) -> 121.58616 | BA40: =AN40/U40 -> 143.8386
...

Sheet Amazon Live Products
D1: Status | E1: SKU | F1: ASIN | G1: Model | H1: Category L1 | I1: Category L2 | J1: Description | K1: HSN Code | L1: FOB (USD) | M1: Previous Price | N1: Freight+Clearance | O1: Duty and Surcharge | P1: DP | Q1: NLC | R1: Referral Fee | S1: Fixed Closing Fee | T1: Fulfillment Fees | U1: Total FBA Fee | V1: AMS | W1: Coupon | X1: Returns Loss | Y1: SMM | Z1: 18% GST in SP | AA1: Business OH | AB1: Finance | AC1: Total Cost | AD1: Margin | AE1: Margin% | AF1: BAU Deal SP | AG1: Other Charges | AH1: Juiter SP | AI1: MRP | AJ1: Gross Margin | AK1: Gross Margin % | AL1: EAN | AN1: Image ASIN | AO1: July 2025 BAU Deal Price
A2: Dollar Conversion Rate | B2: 88 | D2: Live | E2: FBA78980 | F2: B0CDPMX152 | G2: GS-02 | H2: Home & Kitchen | I2: Fabric Care | J2: Nexlev Garment Steamer - Swift | K2: 85167990 | L2: =VLOOKUP(E2,'Margin Calculation'!F:U,16,0) -> 9.45 | M2: =VLOOKUP(E2,'Margin Calculation'!F:V,17,0) -> 9.45 | N2: 0.3 | O2: =VLOOKUP(E2,'Margin Calculation'!F:X,19,0) -> 2.136559 | P2: =(L2+N2+O2)*$B$2 -> 1046.0172 | Q2: =P2*1.18 -> 1234.3003 | R2: =VLOOKUP(E2,'Margin Calculation'!F:AA,22,0) -> 92.25 | S2: 50 | T2: 136 | U2: 322.4 | V2: =AF2*10% -> 204.9 | W2: =AF2*$B$18 -> 20.49 | X2: =AF2*$B$15 -> 102.45 | Y2: =AF2*$B$21 -> 40.98 | Z2: =AF2-(AF2/1.18) -> 312.55932 | AA2: =AF2*$B$16 -> 102.45 | AB2: =AF2*$B$17 -> 61.47 | AC2: =P2+R2+S2+T2+V2+W2+X2+Y2+Z2+AA2+AB2 -> 2169.5665 | AD2: =AF2-AC2 -> -120.56652 | AE2: =AD2/AF2 -> -0.058841639 | AF2: 2049 | AI2: 4999 | AJ2: =(AF2-P2)-Z2 -> 690.42348 | AK2: =AJ2/AF2 -> 0.33695631 | AL2: 8904422503373 | AN2: B0F9P5NFBK | AO2: 2449
A3: 40HQ Freight+Clearance | B3: 2000 | D3: Live | E3: FBA78981 | F3: B0CDPP45BM | G3: SC-01 | H3: Home & Kitchen | I3: Cleaning & Vacumming | J3: Nexlev Steam Cleaner | K3: 85098000 | L3: =VLOOKUP(E3,'Margin Calculation'!F:U,16,0) -> 13.5 | M3: =VLOOKUP(E3,'Margin Calculation'!F:V,17,0) -> 13.4 | N3: 0.4 | O3: =VLOOKUP(E3,'Margin Calculation'!F:X,19,0) -> 3.0494912 | P3: =(L3+N3+O3)*$B$2 -> 1491.5552 | Q3: =P3*1.18 -> 1760.0352 | R3: =VLOOKUP(E3,'Margin Calculation'!F:AA,22,0) -> 161.955 | S3: 50 | T3: 136 | U3: 406.9 | V3: =AF3*10% -> 339.9 | W3: =AF3*$B$18 -> 33.99 | X3: =AF3*$B$15 -> 169.95 | Y3: =AF3*$B$21 -> 67.98 | Z3: =AF3-(AF3/1.18) -> 518.49153 | AA3: =AF3*$B$16 -> 169.95 | AB3: =AF3*$B$17 -> 101.97 | AC3: =P3+R3+S3+T3+V3+W3+X3+Y3+Z3+AA3+AB3 -> 3241.7417 | AD3: =AF3-AC3 -> 157.25825 | AE3: =AD3/AF3 -> 0.046266034 | AF3: 3399 | AI3: 9999 | AJ3: =(AF3-P3)-Z3 -> 1388.9533 | AK3: =AJ3/AF3 -> 0.40863585 | AL3: 8904422503380 | AN3: B0CDPMX152 | AO3: 2099
A4: 40HQ Usable CBM | B4: 68 | D4: Live | E4: FBA78994 | F4: B0CDQ98FDM | G4: NP-01 | H4: Sports, Fitness & Outdoors | I4: Travel Accessories | J4: Neck Pillow with Memory Foam and Striped Texture | K4: 94043090 | L4: =VLOOKUP(E4,'Margin Calculation'!F:U,16,0) -> 2.95 | M4: =VLOOKUP(E4,'Margin Calculation'!F:V,17,0) -> 0 | N4: 0.1 | O4: =VLOOKUP(E4,'Margin Calculation'!F:X,19,0) -> 0.85156164 | P4: =(L4+N4+O4)*$B$2 -> 343.33742 | Q4: =P4*1.18 -> 405.13816 | R4: =VLOOKUP(E4,'Margin Calculation'!F:AA,22,0) -> 69.9 | S4: 25 | T4: 78 | U4: 172.9 | V4: =AF4*10% -> 69.9 | W4: =AF4*$B$18 -> 6.99 | X4: =AF4*$B$15 -> 34.95 | Y4: =AF4*$B$21 -> 13.98 | Z4: =AF4-(AF4/1.18) -> 106.62712 | AA4: =AF4*$B$16 -> 34.95 | AB4: =AF4*$B$17 -> 20.97 | AC4: =P4+R4+S4+T4+V4+W4+X4+Y4+Z4+AA4+AB4 -> 804.60454 | AD4: =AF4-AC4 -> -105.60454 | AE4: =AD4/AF4 -> -0.15107946 | AF4: =VLOOKUP(F4,AN:AO,2,0) -> 699 | AI4: 1499 | AJ4: =(AF4-P4)-Z4 -> 249.03546 | AK4: =AJ4/AF4 -> 0.3562739 | AL4: 8904422503496 | AN4: B0CYSLCRQS | AO4: 2899
A5: Fulfillment Rate/kg | B5: 40 | D5: Live | E5: FBA78995 | F5: B0CDQ55W2M | G5: NP-02 | H5: Sports, Fitness & Outdoors | I5: Travel Accessories | J5: Neck Pillow with Memory Foam (Dark Grey) | K5: 94043090 | L5: =VLOOKUP(E5,'Margin Calculation'!F:U,16,0) -> 2.95 | M5: =VLOOKUP(E5,'Margin Calculation'!F:V,17,0) -> 0 | N5: 0.1 | O5: =VLOOKUP(E5,'Margin Calculation'!F:X,19,0) -> 0.85156164 | P5: =(L5+N5+O5)*$B$2 -> 343.33742 | Q5: =P5*1.18 -> 405.13816 | R5: =VLOOKUP(E5,'Margin Calculation'!F:AA,22,0) -> 69.9 | S5: 25 | T5: 78 | U5: 172.9 | V5: =AF5*10% -> 69.9 | W5: =AF5*$B$18 -> 6.99 | X5: =AF5*$B$15 -> 34.95 | Y5: =AF5*$B$21 -> 13.98 | Z5: =AF5-(AF5/1.18) -> 106.62712 | AA5: =AF5*$B$16 -> 34.95 | AB5: =AF5*$B$17 -> 20.97 | AC5: =P5+R5+S5+T5+V5+W5+X5+Y5+Z5+AA5+AB5 -> 804.60454 | AD5: =AF5-AC5 -> -105.60454 | AE5: =AD5/AF5 -> -0.15107946 | AF5: =VLOOKUP(F5,AN:AO,2,0) -> 699 | AI5: 1999 | AJ5: =(AF5-P5)-Z5 -> 249.03546 | AK5: =AJ5/AF5 -> 0.3562739 | AL5: 8904422503502 | AN5: B0DCK7ZH5P | AO5: 3199
